[[{"duration": 0.147118, "stdout": "", "stderr": "Traceback (most recent call last):\n  File \"/opt/conda/lib/python3.7/site-packages/kaggle_environments/agent.py\", line 50, in get_last_callable\n    exec(code_object, env)\n  File \"/kaggle_simulations/agent/main.py\", line 2, in <module>\n    from agent import agent\n  File \"/kaggle_simulations/agent/agent.py\", line 19, in <module>\n    with open(\"bots_dump/best_bot.json\", \"r\") as f:\nFileNotFoundError: [Errno 2] No such file or directory: 'bots_dump/best_bot.json'\n\nDuring handling of the above exception, another exception occurred:\n\nTraceback (most recent call last):\n  File \"/opt/conda/lib/python3.7/site-packages/kaggle_environments/agent.py\", line 157, in act\n    action = self.agent(*args)\n  File \"/opt/conda/lib/python3.7/site-packages/kaggle_environments/agent.py\", line 123, in callable_agent\n    agent = get_last_callable(raw_agent, path=raw) or raw_agent\n  File \"/opt/conda/lib/python3.7/site-packages/kaggle_environments/agent.py\", line 64, in get_last_callable\n    raise InvalidArgument(\"Invalid raw Python: \" + re"}]]